<?xml version="1.0" ?>
<!-- =================================================================================== -->
<!-- |    This document was autogenerated by xacro from package://ModularBot/urdf/ModularBot.urdf.xacro | -->
<!-- |    EDITING THIS FILE BY HAND IS NOT RECOMMENDED                                 | -->
<!-- =================================================================================== -->
<robot name="ModularBot">
  <!-- <xacro:include filename="$(find modular)/urdf/config.xacro" />
    <xacro:include filename="$(find modular)/urdf/modular.gazebo" /> -->
  <!-- <xacro:property name="pi" value="3.1415" /> -->
  <material name="blue">
    <color rgba="0 0 0.8 1"/>
  </material>
  <material name="black">
    <color rgba="0 0 0 1"/>
  </material>
  <material name="white">
    <color rgba="1 1 1 1"/>
  </material>
  <material name="grey">
    <color rgba="0.5 0.5 0.5 1"/>
  </material>
  <material name="red">
    <color rgba="1 0 0 1"/>
  </material>
  <material name="green">
    <color rgba="0 1 0 1"/>
  </material>
  <material name="yellow">
    <color rgba="1 1 0 1"/>
  </material>
  <material name="tree_green">
    <color rgba="0.13 0.54 0.13 1"/>
  </material>
  <link name="world"/>
  <joint name="world" type="fixed">
    <parent link="world"/>
    <child link="base_link"/>
  </joint>
  <link name="base_link">
    <inertial>
      <mass value="10.0"/>
      <inertia ixx="1.0e-03" ixy="0.0" ixz="0.0" iyy="1.0e-03" iyz="0.0" izz="1.0e-03"/>
    </inertial>
  </link>
  <gazebo>
    <plugin filename="libxbot2_gz_joint_server.so" name="xbot2_gz_joint_server">
      <pid>
	      <gain d="10" name="small_mot" p="100"/>
      	<gain d="50" name="medium_mot" p="500"/>
      	<gain d="100" name="big_mot" p="1000"/>        
	      <gain name="J1_A" profile="medium_mot"/>
        <gain name="gripper_A_finger_joint1" profile="medium_mot"/>
        <gain name="gripper_A_finger_joint2" profile="medium_mot"/>
      </pid>
      
    </plugin>
  </gazebo>
  <joint name="fixed_J1_A" type="fixed">
    <axis rpy="0 0 0" xyz="0 0 1"/>
    <parent link="base_link"/>
    <child link="J1_A_stator"/>
    <origin rpy="0.0 -0.0 0.0" xyz="0.0 0.0 0.0"/>
  </joint>
  <link name="J1_A_stator">
    <visual>
      <!-- Load mesh. Rotate the origin frame (this is because of how the .stl was saved) -->
      <origin rpy="0.0 0.0 0.0" xyz="0.0 0.0 0.0"/>
      <geometry>
        <mesh filename="package://ModularBot/database/modular/meshes/elbow_base.stl" scale="0.001 0.001 0.001"/>
      </geometry>
      <material name="tree_green"/>
    </visual>
    <collision>
      <origin rpy="0.0 0.0 0.0" xyz="0.0 0.0 0.0"/>
      <geometry>
        <mesh filename="package://ModularBot/database/modular/meshes/simple/elbow_base.stl" scale="0.001 0.001 0.001"/>
      </geometry>
    </collision>
    <inertial>
      <origin rpy="0 0 0" xyz="0.0 -0.013666345 0.095904755"/>
      <mass value="1.8627994"/>
      <inertia ixx="0.0080669105" ixy="6.8780537e-06" ixz="2.4976943e-05" iyy="0.0069731259" iyz="0.00033158425" izz="0.0037855995"/>
    </inertial>
  </link>
  <gazebo reference="J1_A_stator">
    <mu1>0.2</mu1>
    <mu2>0.2</mu2>
    <kp>1000000.0</kp>
    <kd>1.0</kd>
    <maxVel>0.0</maxVel>
    <minDepth>0.0001</minDepth>
    <material>Gazebo/Blue</material>
  </gazebo>
  <joint name="J1_A" type="revolute">
    <axis rpy="0 0 0" xyz="0 0 1"/>
    <parent link="J1_A_stator"/>
    <child link="L_1_A"/>
    <origin rpy="-1.57 -0.0 0.0" xyz="0.0 0.0721499771235 0.132057454972"/>
    <limit effort="147" lower="-2.0" upper="2.0" velocity="3.9"/>
  </joint>
  <!-- <xacro:property name="visual" value="${module['visual']['mesh_body_1']}"/> -->
  <link name="L_1_A">
    <visual>
      <!-- Load mesh. Rotate the origin frame (this is because of how the .stl was saved) -->
      <origin rpy="0.0 3.14 0.0" xyz="0.0 0.0 -0.072"/>
      <geometry>
        <mesh filename="package://ModularBot/database/modular/meshes/elbow_link.stl" scale="0.001 0.001 0.001"/>
      </geometry>
      <material name="tree_green"/>
    </visual>
    <collision>
      <origin rpy="0.0 3.14 0.0" xyz="0.0 0.0 -0.072"/>
      <geometry>
        <mesh filename="package://ModularBot/database/modular/meshes/simple/elbow_link.stl" scale="0.001 0.001 0.001"/>
      </geometry>
    </collision>
    <!--inertial parameters for ORANGE rotating part. wrt a point on one end of the rod-->
    <!-- <inertial>
                <origin xyz="0 0 -0.002265" rpy="0 0 0"/>
                <mass value="0.153466"/>
                <inertia
                        ixx="0.000034763" ixy="0.0" ixz="0.0"
                        iyy="0.000034827" iyz="0.0"
                        izz="0.000031822"/>
            </inertial> -->
    <inertial>
      <origin rpy="0 0 0" xyz="0.0 -0.040608854 -0.038467625"/>
      <mass value="1.1036463"/>
      <inertia ixx="0.0048243291" ixy="6.7819559e-06" ixz="-3.6661875e-06" iyy="0.0024139151" iyz="-0.0010484708" izz="0.0049751925"/>
    </inertial>
  </link>
  <joint name="fixed_L_1_A_rotor_fast" type="fixed">
    <axis rpy="0 0 0" xyz="0 0 1"/>
    <parent link="L_1_A"/>
    <child link="L_1_A_rotor_fast"/>
    <origin rpy="0.0 -0.0 0.0" xyz="0.0 0.0 0.0"/>
  </joint>
  <link name="L_1_A_rotor_fast">
    <inertial>
      <origin rpy="0 0 0" xyz="0.0 0.0 -0.0978986"/>
      <mass value="0.197124"/>
      <inertia ixx="0.00016128216" ixy="-2.4229e-07" ixz="3.771218e-06" iyy="0.00016138868" iyz="-2.4900687e-06" izz="0.1287638"/>
      <!-- ixz="${ gear_ratio * module['dynamics']['body_2_fast']['inertia_tensor']['I_xz'] }" -->
      <!-- iyz="${ gear_ratio * module['dynamics']['body_2_fast']['inertia_tensor']['I_yz'] }" -->
      <!-- izz="${module['dynamics']['body_2_fast']['inertia_tensor']['I_zz'] }" -->
    </inertial>
  </link>
  <link name="gripper_A">
    <visual>
      <!-- Load mesh. Rotate the origin frame (this is because of how the .stl was saved) -->
      <origin rpy="0.0 0.0 0.0" xyz="0.0 0.0 0.0"/>
      <geometry>
        <mesh filename="package://ModularBot/database/modular/meshes/gripper_outer_assembly_simplified.stl" scale="0.001 0.001 0.001"/>
      </geometry>
      <material name="tree_green"/>
    </visual>
    <collision>
      <origin rpy="0.0 0.0 0.0" xyz="0.0 0.0 0.0"/>
      <geometry>
        <mesh filename="package://ModularBot/database/modular/meshes/simple/gripper_outer_assembly_simplified.stl" scale="0.001 0.001 0.001"/>
      </geometry>
    </collision>
    <inertial>
      <origin rpy="0 0 0" xyz="0.0 0.0 0.0798"/>
      <mass value="1.182"/>
      <inertia ixx="0.0025968127" ixy="0.0" ixz="0.0" iyy="0.0020344466" iyz="0.0" izz="0.0014696895"/>
    </inertial>
  </link>
  <!-- add fingers -->
  <link name="gripper_A_leftfinger">
    <visual>
      <geometry>
        <mesh filename="package://ModularBot/database/modular/meshes/fingerup_7_raised.stl" scale="0.001 0.001 0.001"/>
      </geometry>
      <material name="grey"/>
    </visual>
    <collision>
      <geometry>
        <mesh filename="package://ModularBot/database/modular/meshes/simple/fingerup_7_raised.stl" scale="0.001 0.001 0.001"/>
      </geometry>
    </collision>
    <!-- for simulation -->
    <inertial>
      <origin rpy="0 0 0" xyz="0.0 0.0 0.0"/>
      <mass value="0.001"/>
      <inertia ixx="1e-05" ixy="0.0" ixz="0.0" iyy="1e-05" iyz="0.0" izz="1e-05"/>
    </inertial>
  </link>
  <link name="gripper_A_rightfinger">
    <visual>
      <origin rpy="0 0 3.14159265359" xyz="0 0 0"/>
      <geometry>
        <mesh filename="package://ModularBot/database/modular/meshes/fingerup_7_raised.stl" scale="0.001 0.001 0.001"/>
      </geometry>
      <material name="grey"/>
    </visual>
    <collision>
      <origin rpy="0 0 3.14159265359" xyz="0 0 0"/>
      <geometry>
        <mesh filename="package://ModularBot/database/modular/meshes/simple/fingerup_7_raised.stl" scale="0.001 0.001 0.001"/>
      </geometry>
    </collision>
    <!-- for simulation -->
    <inertial>
      <origin rpy="0 0 0" xyz="0.0 0.0 0.0"/>
      <mass value="0.001"/>
      <inertia ixx="1e-05" ixy="0.0" ixz="0.0" iyy="1e-05" iyz="0.0" izz="1e-05"/>
    </inertial>
  </link>
  <!-- Add joints -->
  <joint name="gripper_A_finger_joint1" type="fixed">
    <parent link="gripper_A"/>
    <child link="gripper_A_leftfinger"/>
    <origin rpy="0 0 0" xyz="0 0 0.1275"/>
    <axis xyz="0 -1 0"/>
    <limit effort="20.0" lower="0.0" upper="0.05" velocity="0.2"/>
  </joint>
  <joint name="gripper_A_finger_joint2" type="fixed">
    <parent link="gripper_A"/>
    <child link="gripper_A_rightfinger"/>
    <origin rpy="0 0 0" xyz="0 0 0.1275"/>
    <limit effort="20.0" lower="0.0" upper="0.05" velocity="0.2"/>
    <axis xyz="0 1 0"/>
  </joint>
  <!-- Add TCP -->
  <link name="TCP_gripper_A"/>
  <joint name="fixed_TCP_gripper_A" type="fixed">
    <axis rpy="0 0 0" xyz="0 0 1"/>
    <parent link="gripper_A"/>
    <child link="TCP_gripper_A"/>
    <origin rpy="0.0 0.0 0.0" xyz="0.0 0.0 0.1985"/>
  </joint>
  <joint name="gripper_A_fixed_joint" type="fixed">
    <axis rpy="0 0 0" xyz="0 0 1"/>
    <parent link="L_1_A"/>
    <child link="gripper_A"/>
    <origin rpy="1.57 -0.0 0.0" xyz="0.0 -0.131999958147 -0.0720448848742"/>
  </joint>
</robot>
